Workbook

Sheet NSE
A1: instrument_token | B1: exchange_token | C1: tradingsymbol | D1: name | E1: last_price | F1: expiry | G1: strike | H1: tick_size | I1: lot_size | J1: instrument_type | K1: segment | L1: exchange | M1: GOLD | N1: name | O1: nav
A2: 256265 | B2: 1001 | C2: NIFTY 50 | D2: NIFTY 50 | E2: 0 | G2: 0 | H2: 0 | I2: 0 | J2: EQ | K2: INDICES | L2: NSE
A3: 256777 | B3: 1003 | C3: NIFTY MIDCAP 100 | D3: NIFTY MIDCAP 100 | E3: 0 | G3: 0 | H3: 0 | I3: 0 | J3: EQ | K3: INDICES | L3: NSE
A4: 260105 | B4: 1016 | C4: NIFTY BANK | D4: NIFTY BANK | E4: 0 | G4: 0 | H4: 0 | I4: 0 | J4: EQ | K4: INDICES | L4: NSE
A5: 260617 | B5: 1018 | C5: NIFTY 100 | D5: NIFTY 100 | E5: 0 | G5: 0 | H5: 0 | I5: 0 | J5: EQ | K5: INDICES | L5: NSE
A6: 257033 | B6: 1004 | C6: NIFTY DIV OPPS 50 | D6: NIFTY DIV OPPS 50 | E6: 0 | G6: 0 | H6: 0 | I6: 0 | J6: EQ | K6: INDICES | L6: NSE
A7: 257289 | B7: 1005 | C7: NIFTY COMMODITIES | D7: NIFTY COMMODITIES | E7: 0 | G7: 0 | H7: 0 | I7: 0 | J7: EQ | K7: INDICES | L7: NSE
A8: 257545 | B8: 1006 | C8: NIFTY CONSUMPTION | D8: NIFTY CONSUMPTION | E8: 0 | G8: 0 | H8: 0 | I8: 0 | J8: EQ | K8: INDICES | L8: NSE
A9: 257801 | B9: 1007 | C9: NIFTY FIN SERVICE | D9: NIFTY FIN SERVICE | E9: 0 | G9: 0 | H9: 0 | I9: 0 | J9: EQ | K9: INDICES | L9: NSE
A10: 258825 | B10: 1011 | C10: NIFTY50 PR 2X LEV | D10: NIFTY50 PR 2X LEV | E10: 0 | G10: 0 | H10: 0 | I10: 0 | J10: EQ | K10: INDICES | L10: NSE
A11: 259081 | B11: 1012 | C11: NIFTY50 PR 1X INV | D11: NIFTY50 PR 1X INV | E11: 0 | G11: 0 | H11: 0 | I11: 0 | J11: EQ | K11: INDICES | L11: NSE
A12: 259337 | B12: 1013 | C12: NIFTY50 TR 2X LEV | D12: NIFTY50 TR 2X LEV | E12: 0 | G12: 0 | H12: 0 | I12: 0 | J12: EQ | K12: INDICES | L12: NSE
A13: 259593 | B13: 1014 | C13: NIFTY50 TR 1X INV | D13: NIFTY50 TR 1X INV | E13: 0 | G13: 0 | H13: 0 | I13: 0 | J13: EQ | K13: INDICES | L13: NSE
... A177: 36865 | B177: 144 | C177: GODREJAGRO | D177: GODREJ AGROVET | E177: 0 | G177: 0 | H177: 0.05 | I177: 1 | J177: EQ | K177: NSE | L177: NSE
A178: 38145 | B178: 149 | C178: SGBSEP28VI-GB | D178: 2.50%GOLDBONDS2028SR-VI | E178: 0 | G178: 0 | H178: 0.01 | I178: 1 | J178: EQ | K178: NSE | L178: NSE | M178: Yes
A179: 39425 | B179: 154 | C179: APCOTEXIND | D179: APCOTEX INDUSTRIES LIMITE | E179: 0 | G179: 0 | H179: 0.05 | I179: 1 | J179: EQ | K179: NSE | L179: NSE
A180: 40193 | B180: 157 | C180: APOLLOHOSP | D180: APOLLO HOSPITALS ENTER. L | E180: 0 | G180: 0 | H180: 0.5 | I180: 1 | J180: EQ | K180: NSE | L180: NSE
A181: 40449 | B181: 158 | C181: 67MH28-SG | D181: SDL MH 6.7% 2028 | E181: 0 | G181: 0 | H181: 0.01 | I181: 100 | J181: EQ | K181: NSE | L181: NSE
A182: 41217 | B182: 161 | C182: 674UP30-SG | D182: SDL UP 6.74% 2030 | E182: 0 | G182: 0 | H182: 0.01 | I182: 100 | J182: EQ | K182: NSE | L182: NSE
A183: 41473 | B183: 162 | C183: MILTON-ST | D183: MILTON INDUSTRIES | E183: 0 | G183: 0 | H183: 0.05 | I183: 4400 | J183: EQ | K183: NSE | L183: NSE
A184: 41729 | B184: 163 | C184: APOLLOTYRE | D184: APOLLO TYRES | E184: 0 | G184: 0 | H184: 0.05 | I184: 1 | J184: EQ | K184: NSE | L184: NSE
A185: 41985 | B185: 164 | C185: 68AS30-SG | D185: SDL AS 6.8% 2030 | E185: 0 | G185: 0 | H185: 0.01 | I185: 100 | J185: EQ | K185: NSE | L185: NSE
A186: 42241 | B186: 165 | C186: 674GA30-SG | D186: SDL GA 6.74% 2030 | E186: 0 | G186: 0 | H186: 0.01 | I186: 100 | J186: EQ | K186: NSE | L186: NSE
A187: 42497 | B187: 166 | C187: ANDHRAPAP | D187: ANDHRA PAPER | E187: 0 | G187: 0 | H187: 0.01 | I187: 1 | J187: EQ | K187: NSE | L187: NSE
A188: 42753 | B188: 167 | C188: 67GJ30-SG | D188: SDL GJ 6.7% 2030 | E188: 0 | G188: 0 | H188: 0.01 | I188: 100 | J188: EQ | K188: NSE | L188: NSE
A189: 43521 | B189: 170 | C189: 67KA30-SG | D189: SDL KA 6.7% 2030 | E189: 0 | G189: 0 | H189: 0.01 | I189: 100 | J189: EQ | K189: NSE | L189: NSE
A190: 43777 | B190: 171 | C190: 672RJ30-SG | D190: SDL RJ 6.72% 2030 | E190: 0 | G190: 0 | H190: 0.01 | I190: 100 | J190: EQ | K190: NSE | L190: NSE
... A196: 47361 | B196: 185 | C196: 678MH32-SG | D196: SDL MH 6.78% 2032 | E196: 0 | G196: 0 | H196: 0.01 | I196: 100 | J196: EQ | K196: NSE | L196: NSE
A197: 47617 | B197: 186 | C197: 850NHAI29-N5 | E197: 0 | G197: 0 | H197: 0.01 | I197: 1 | J197: EQ | K197: NSE | L197: NSE | N197: blank
A198: 49153 | B198: 192 | C198: 875NHAI29-N6 | E198: 0 | G198: 0 | H198: 0.01 | I198: 1 | J198: EQ | K198: NSE | L198: NSE | N198: blank
A199: 49409 | B199: 193 | C199: ARVIND | D199: ARVIND | E199: 0 | G199: 0 | H199: 0.05 | I199: 1 | J199: EQ | K199: NSE | L199: NSE
A200: 50945 | B200: 199 | C200: MASFIN | D200: MAS FINANCIAL SERV | E200: 0 | G200: 0 | H200: 0.05 | I200: 1 | J200: EQ | K200: NSE | L200: NSE
A201: 51457 | B201: 201 | C201: UNIDT | D201: UNITED DRILLING TOOLS | E201: 0 | G201: 0 | H201: 0.01 | I201: 1 | J201: EQ | K201: NSE | L201: NSE
A202: 51969 | B202: 203 | C202: ASHAPURMIN | D202: ASHAPURA MINECHEM | E202: 0 | G202: 0 | H202: 0.05 | I202: 1 | J202: EQ | K202: NSE | L202: NSE
A203: 52737 | B203: 206 | C203: ASHIMASYN | D203: ASHIMA | E203: 0 | G203: 0 | H203: 0.01 | I203: 1 | J203: EQ | K203: NSE | L203: NSE
A204: 54273 | B204: 212 | C204: ASHOKLEY | D204: ASHOK LEYLAND | E204: 0 | G204: 0 | H204: 0.01 | I204: 1 | J204: EQ | K204: NSE | L204: NSE
A205: 56321 | B205: 220 | C205: IEX | D205: INDIAN ENERGY EXC | E205: 0 | G205: 0 | H205: 0.01 | I205: 1 | J205: EQ | K205: NSE | L205: NSE
A206: 60161 | B206: 235 | C206: AAKASH | D206: AAKASH EXPLORATION SER L | E206: 0 | G206: 0 | H206: 0.01 | I206: 1 | J206: EQ | K206: NSE | L206: NSE
A207: 60417 | B207: 236 | C207: ASIANPAINT | D207: ASIAN PAINTS | E207: 0 | G207: 0 | H207: 0.1 | I207: 1 | J207: EQ | K207: NSE | L207: NSE
A208: 62721 | B208: 245 | C208: ADL | D208: ARCHIDPLY DECOR | E208: 0 | G208: 0 | H208: 0.01 | I208: 1 | J208: EQ | K208: NSE | L208: NSE
...

Sheet zerodhaNSEname
A1: instrument_token | B1: exchange_token | C1: tradingsymbol | D1: name
A2: 1025 | B2: 4 | C2: 21STCENMGM | D2: 21ST CENTURY MGMT SERVICE
A3: 1793 | B3: 7 | C3: AARTIIND | D3: AARTI INDUSTRIES
A4: 3329 | B4: 13 | C4: ABB | D4: ABB INDIA
A5: 4353 | B5: 17 | C5: GATECHDVR | D5: GACM TECHNOLOGIES
A6: 4865 | B6: 19 | C6: STYRENIX | D6: STYRENIX PERFORMANCE
A7: 5633 | B7: 22 | C7: ACC | D7: ACC
A8: 6401 | B8: 25 | C8: ADANIENT | D8: ADANI ENTERPRISES
A9: 8705 | B9: 34 | C9: ADOR | D9: ADOR WELDING
A10: 10241 | B10: 40 | C10: AEGISLOG | D10: AEGIS LOGISTICS
A11: 11777 | B11: 46 | C11: SANWARIA-BZ | D11: SANWARIA CONSUMER
A12: 12289 | B12: 48 | C12: HAPPSTMNDS | D12: HAPPIEST MINDS TECHNO
A13: 20225 | B13: 79 | C13: ALEMBICLTD | D13: ALEMBIC
... A2683: 268041 | B2683: 1047 | C2683: NIFTY 500 | D2683: NIFTY 500

Sheet F&O list
A1: SL NO | B1: F&O STOCKS NAME | C1: SYMBOL | D1: LOT SIZE | E1: zerodha name
A2: 1 | B2: Nifty Bank | C2: BANKNIFTY | D2: 30 | E2: NIFTY BANK
A3: 2 | B3: Finnifty | C3: FINNIFTY | D3: 60 | E3: NIFTY FIN SERVICE
A4: 3 | B4: Nifty Midcap Select | C4: MIDCPNIFTY | D4: 120 | E4: NIFTY MIDCAP SELECT (MIDCPNIFTY)
A5: 4 | B5: Nifty 50 | C5: NIFTY | D5: 65 | E5: NIFTY 50
A6: 5 | B6: Nifty Next 50 | C6: NIFTY NEXT 50 | D6: 25 | E6: NIFTY NEXT 50
A7: 6 | B7: 360 One WAM | C7: 360ONE | D7: 500 | E7: =VLOOKUP(C7,zerodhaNSEname!C:D,2,0) -> 360 ONE WAM
A8: 7 | B8: ABB | C8: ABB | D8: 125 | E8: =VLOOKUP(C8,zerodhaNSEname!C:D,2,0) -> ABB INDIA
A9: 8 | B9: Aditya Birla Capital | C9: ABCAPITAL | D9: 3100 | E9: =VLOOKUP(C9,zerodhaNSEname!C:D,2,0) -> ADITYA BIRLA CAPITAL
A10: 9 | B10: Adani Energy Solutions | C10: ADANIENSOL | D10: 675 | E10: =VLOOKUP(C10,zerodhaNSEname!C:D,2,0) -> ADANI ENERGY SOLUTION
A11: 10 | B11: Adani Enterprises | C11: ADANIENT | D11: 300 | E11: =VLOOKUP(C11,zerodhaNSEname!C:D,2,0) -> ADANI ENTERPRISES
A12: 11 | B12: Adani Green Energy | C12: ADANIGREEN | D12: 600 | E12: =VLOOKUP(C12,zerodhaNSEname!C:D,2,0) -> ADANI GREEN ENERGY
A13: 12 | B13: Adani Ports & SEZ | C13: ADANIPORTS | D13: 475 | E13: =VLOOKUP(C13,zerodhaNSEname!C:D,2,0) -> ADANI PORT & SEZ
A14: 13 | B14: Alkem Laboratories | C14: ALKEM | D14: 125 | E14: =VLOOKUP(C14,zerodhaNSEname!C:D,2,0) -> ALKEM LABORATORIES
A15: 14 | B15: Amber Enterprises | C15: AMBER | D15: 100 | E15: =VLOOKUP(C15,zerodhaNSEname!C:D,2,0) -> AMBER ENTERPRISES (I)
A16: 15 | B16: Ambuja Cements | C16: AMBUJACEM | D16: 1050 | E16: =VLOOKUP(C16,zerodhaNSEname!C:D,2,0) -> AMBUJA CEMENTS
A17: 16 | B17: Angel One | C17: ANGELONE | D17: 250 | E17: =VLOOKUP(C17,zerodhaNSEname!C:D,2,0) -> ANGEL ONE
A18: 17 | B18: APL Apollo Tubes | C18: APLAPOLLO | D18: 350 | E18: =VLOOKUP(C18,zerodhaNSEname!C:D,2,0) -> APL APOLLO TUBES
... A191: 190 | B191: Tata Elxsi | C191: TATAELXSI | D191: 100 | E191: =VLOOKUP(C191,zerodhaNSEname!C:D,2,0) -> TATA ELXSI
A192: 191 | B192: Tata Motors | C192: TATAMOTORS | D192: 800 | E192: TATA MOTORS PASS VEH
A193: 192 | B193: Tata Power | C193: TATAPOWER | D193: 1450 | E193: =VLOOKUP(C193,zerodhaNSEname!C:D,2,0) -> TATA POWER CO
A194: 193 | B194: Tata Steel | C194: TATASTEEL | D194: 5500 | E194: =VLOOKUP(C194,zerodhaNSEname!C:D,2,0) -> TATA STEEL
A195: 194 | B195: Tata Technologies | C195: TATATECH | D195: 800 | E195: =VLOOKUP(C195,zerodhaNSEname!C:D,2,0) -> TATA TECHNOLOGIES
A196: 195 | B196: Tata Consultancy Services | C196: TCS | D196: 175 | E196: =VLOOKUP(C196,zerodhaNSEname!C:D,2,0) -> TATA CONSULTANCY SERV LT
A197: 196 | B197: Tech Mahindra | C197: TECHM | D197: 600 | E197: =VLOOKUP(C197,zerodhaNSEname!C:D,2,0) -> TECH MAHINDRA
A198: 197 | B198: Tube Investment | C198: TIINDIA | D198: 200 | E198: =VLOOKUP(C198,zerodhaNSEname!C:D,2,0) -> TUBE INVEST OF INDIA
A199: 198 | B199: Titagarh Rail Systems | C199: TITAGARH | D199: 725 | E199: =VLOOKUP(C199,zerodhaNSEname!C:D,2,0) -> TITAGARH RAIL SYSTEMS
A200: 199 | B200: Titan | C200: TITAN | D200: 175 | E200: =VLOOKUP(C200,zerodhaNSEname!C:D,2,0) -> TITAN COMPANY
A201: 200 | B201: Torrent Pharmaceuticals | C201: TORNTPHARM | D201: 250 | E201: =VLOOKUP(C201,zerodhaNSEname!C:D,2,0) -> TORRENT PHARMACEUTICALS L
A202: 201 | B202: Torrent Power | C202: TORNTPOWER | D202: 375 | E202: =VLOOKUP(C202,zerodhaNSEname!C:D,2,0) -> TORRENT POWER
A203: 202 | B203: Trent | C203: TRENT | D203: 100 | E203: =VLOOKUP(C203,zerodhaNSEname!C:D,2,0) -> TRENT
A204: 203 | B204: TVS Motors | C204: TVSMOTOR | D204: 350 | E204: =VLOOKUP(C204,zerodhaNSEname!C:D,2,0) -> TVS MOTOR COMPANY
... A215: 214 | B215: Zydus Life Science | C215: ZYDUSLIFE | D215: 900 | E215: =VLOOKUP(C215,zerodhaNSEname!C:D,2,0) -> ZYDUS LIFESCIENCES
